Workbook

Sheet TARIFAS CRM
A1: COMERCIALIZADORA | B1: TIPO | C1: ENERGIA | D1: TARIFA | E1: PEAJE | F1: POTENCIA 1 | G1: POTENCIA 2 | H1: POTENCIA 3 | I1: POTENCIA 4 | J1: POTENCIA 5 | K1: POTENCIA 6 | L1: T. FIJO GAS | M1: ENERGIA 1 | N1: ENERGIA 2 | O1: ENERGIA 3 | P1: ENERGIA 4 | Q1: ENERGIA 5 | R1: ENERGIA 6 | S1: T. VARIABLE GAS | T1: DESCUENTO | U1: OBJERVACIONES DESCUENTOS | V1: COMISION | W1: PERMANENCIA | X1: EXCEDENTES | Y1: BATERIA VIRTUAL | Z1: FECHA CARGA
A2: NATURGY | B2: RESIDENCIAL | C2: LUZ | D2: POR USO LUZ | E2: 2.0 | F2: 0.110283 | G2: 0.033469 | M2: 0.120471 | N2: 0.120471 | O2: 0.120471 | V2: 70 | W2: 0 | X2: 0.07 | Y2: SI | Z2: SELLO DE FECHA Y HORA
A3: NATURGY | B3: RESIDENCIAL | C3: LUZ | D3: NOCHE | E3: 2.0 | F3: 0.110283 | G3: 0.033469 | M3: 0.190465 | N3: 0.117512 | O3: 0.082673 | V3: 70 | W3: 0 | X3: 0.07 | Y3: SI | Z3: SELLO DE FECHA Y HORA
A4: NATURGY | B4: PYMES | C4: LUZ | D4: PLAN FIJO ONE TRIHORARIO | E4: 2.0 | F4: =+'Naturgy Pymes'!F17 -> 0.12297298 | G4: =+'Naturgy Pymes'!G17 -> 0.043976022 | M4: =+'Naturgy Pymes'!S17 -> 0.190964 | N4: =+'Naturgy Pymes'!T17 -> 0.117811 | O4: =+'Naturgy Pymes'!U17 -> 0.082473 | V4: SEGÚN TABLA CONSUMO | W4: 12M | X4: 0.07 | Y4: SI | Z4: SELLO DE FECHA Y HORA
A5: NATURGY | B5: PYMES | C5: LUZ | D5: PLAN FIJO TRIHORARIO | E5: 2.0 | F5: =+'Naturgy Pymes'!F17 -> 0.12297298 | G5: =+'Naturgy Pymes'!G17 -> 0.043976022 | M5: =+'Naturgy Pymes'!L17 -> 0.206464 | N5: =+'Naturgy Pymes'!M17 -> 0.133311 | O5: =+'Naturgy Pymes'!N17 -> 0.097973 | V5: SEGÚN TABLA CONSUMO | W5: 12M | X5: 0.07 | Y5: SI | Z5: SELLO DE FECHA Y HORA
A6: NATURGY | B6: PYMES | C6: LUZ | D6: PLAN FIJO SUPRA TRIHORARIO | E6: 2.0 | F6: =+'Naturgy Pymes'!F17 -> 0.12297298 | G6: =+'Naturgy Pymes'!G17 -> 0.043976022 | M6: =+'Naturgy Pymes'!Z17 -> 0.219465 | N6: =+'Naturgy Pymes'!AA17 -> 0.146312 | O6: =+'Naturgy Pymes'!AB17 -> 0.110973 | V6: SEGÚN TABLA CONSUMO | W6: 12M | X6: 0.07 | Y6: SI | Z6: SELLO DE FECHA Y HORA
A7: NATURGY | B7: PYMES | C7: LUZ | D7: PLAN FIJO ONE | E7: 2.0 | F7: =+'Naturgy Pymes'!F10 -> 0.12297298 | G7: =+'Naturgy Pymes'!G10 -> 0.043976022 | M7: =+'Naturgy Pymes'!S10 -> 0.120671 | N7: =+'Naturgy Pymes'!S10 -> 0.120671 | O7: =+'Naturgy Pymes'!S10 -> 0.120671 | V7: SEGÚN TABLA CONSUMO | W7: 12M | X7: 0.07 | Y7: SI | Z7: SELLO DE FECHA Y HORA
A8: NATURGY | B8: PYMES | C8: LUZ | D8: PLAN FIJO | E8: 2.0 | F8: =+'Naturgy Pymes'!F10 -> 0.12297298 | G8: =+'Naturgy Pymes'!G10 -> 0.043976022 | M8: =+'Naturgy Pymes'!L10 -> 0.136171 | N8: =+'Naturgy Pymes'!L10 -> 0.136171 | O8: =+'Naturgy Pymes'!L10 -> 0.136171 | V8: SEGÚN TABLA CONSUMO | W8: 12M | X8: 0.07 | Y8: SI | Z8: SELLO DE FECHA Y HORA
A9: NATURGY | B9: PYMES | C9: LUZ | D9: PLAN FIJO SUPRA | E9: 2.0 | F9: =+'Naturgy Pymes'!F10 -> 0.12297298 | G9: =+'Naturgy Pymes'!G10 -> 0.043976022 | M9: =+'Naturgy Pymes'!Z10 -> 0.149171 | N9: =+'Naturgy Pymes'!Z10 -> 0.149171 | O9: =+'Naturgy Pymes'!Z10 -> 0.149171 | V9: SEGÚN TABLA CONSUMO | W9: 12M | X9: 0.07 | Y9: SI | Z9: SELLO DE FECHA Y HORA
A10: NATURGY | B10: PYMES | C10: LUZ | D10: PLAN FIJO ONE | E10: 3.0 | F10: =+'Naturgy Pymes'!F18 -> 0.057927649 | G10: =+'Naturgy Pymes'!G18 -> 0.031189775 | H10: =+'Naturgy Pymes'!H18 -> 0.014378597 | I10: =+'Naturgy Pymes'!I18 -> 0.012747912 | J10: =+'Naturgy Pymes'!J18 -> 0.0089877041 | K10: =+'Naturgy Pymes'!K18 -> 0.0060519452 | M10: =+'Naturgy Pymes'!S18 -> 0.183593 | N10: =+'Naturgy Pymes'!T18 -> 0.158014 | O10: =+'Naturgy Pymes'!U18 -> 0.134925 | P10: =+'Naturgy Pymes'!V18 -> 0.121236 | Q10: =+'Naturgy Pymes'!W18 -> 0.114444 | R10: =+'Naturgy Pymes'!X18 -> 0.106808 | V10: SEGÚN TABLA CONSUMO | W10: 12M | X10: 0.07 | Y10: SI | Z10: SELLO DE FECHA Y HORA
A11: NATURGY | B11: PYMES | C11: LUZ | D11: PLAN FIJO | E11: 3.0 | F11: =+'Naturgy Pymes'!F18 -> 0.057927649 | G11: =+'Naturgy Pymes'!G18 -> 0.031189775 | H11: =+'Naturgy Pymes'!H18 -> 0.014378597 | I11: =+'Naturgy Pymes'!I18 -> 0.012747912 | J11: =+'Naturgy Pymes'!J18 -> 0.0089877041 | K11: =+'Naturgy Pymes'!K18 -> 0.0060519452 | M11: =+'Naturgy Pymes'!L18 -> 0.195993 | N11: =+'Naturgy Pymes'!M18 -> 0.170414 | O11: =+'Naturgy Pymes'!N18 -> 0.147424 | P11: =+'Naturgy Pymes'!O18 -> 0.133736 | Q11: =+'Naturgy Pymes'!P18 -> 0.127043 | R11: =+'Naturgy Pymes'!Q18 -> 0.119208 | V11: SEGÚN TABLA CONSUMO | W11: 12M | X11: 0.07 | Y11: SI | Z11: SELLO DE FECHA Y HORA
A12: NATURGY | B12: PYMES | C12: LUZ | D12: PLAN FIJO SUPRA | E12: 3.0 | F12: =+'Naturgy Pymes'!F18 -> 0.057927649 | G12: =+'Naturgy Pymes'!G18 -> 0.031189775 | H12: =+'Naturgy Pymes'!H18 -> 0.014378597 | I12: =+'Naturgy Pymes'!I18 -> 0.012747912 | J12: =+'Naturgy Pymes'!J18 -> 0.0089877041 | K12: =+'Naturgy Pymes'!K18 -> 0.0060519452 | M12: =+'Naturgy Pymes'!Z18 -> 0.215493 | N12: =+'Naturgy Pymes'!AA18 -> 0.189914 | O12: =+'Naturgy Pymes'!AB18 -> 0.166925 | P12: =+'Naturgy Pymes'!AC18 -> 0.153235 | Q12: =+'Naturgy Pymes'!AD18 -> 0.146543 | R12: =+'Naturgy Pymes'!AE18 -> 0.138708 | V12: SEGÚN TABLA CONSUMO | W12: 12M | X12: 0.07 | Y12: SI | Z12: SELLO DE FECHA Y HORA
A13: NATURGY | B13: PYMES | C13: LUZ | D13: PLAN FIJO ONE | E13: 6.1 | F13: =+'Naturgy Pymes'!F19 -> 0.081083211 | G13: =+'Naturgy Pymes'!G19 -> 0.042506038 | H13: =+'Naturgy Pymes'!H19 -> 0.018635277 | I13: =+'Naturgy Pymes'!I19 -> 0.014777622 | J13: =+'Naturgy Pymes'!J19 -> 0.0058222356 | K13: =+'Naturgy Pymes'!K19 -> 0.002751189 | V13: SEGÚN TABLA CONSUMO | W13: 12M | X13: 0.07 | Y13: SI | Z13: SELLO DE FECHA Y HORA
A14: NATURGY | B14: PYMES | C14: LUZ | D14: PLAN FIJO | E14: 6.1 | F14: =+'Naturgy Pymes'!F19 -> 0.081083211 | G14: =+'Naturgy Pymes'!G19 -> 0.042506038 | H14: =+'Naturgy Pymes'!H19 -> 0.018635277 | I14: =+'Naturgy Pymes'!I19 -> 0.014777622 | J14: =+'Naturgy Pymes'!J19 -> 0.0058222356 | K14: =+'Naturgy Pymes'!K19 -> 0.002751189 | V14: SEGÚN TABLA CONSUMO | W14: 12M | X14: 0.07 | Y14: SI | Z14: SELLO DE FECHA Y HORA
A15: NATURGY | B15: PYMES | C15: LUZ | D15: PLAN FIJO SUPRA | E15: 6.1 | F15: =+'Naturgy Pymes'!F19 -> 0.081083211 | G15: =+'Naturgy Pymes'!G19 -> 0.042506038 | H15: =+'Naturgy Pymes'!H19 -> 0.018635277 | I15: =+'Naturgy Pymes'!I19 -> 0.014777622 | J15: =+'Naturgy Pymes'!J19 -> 0.0058222356 | K15: =+'Naturgy Pymes'!K19 -> 0.002751189 | V15: SEGÚN TABLA CONSUMO | W15: 12M | X15: 0.07 | Y15: SI | Z15: SELLO DE FECHA Y HORA
A16: NATURGY | B16: RESIDENCIAL | C16: GAS | D16: POR USO GAS | E16: RL.1 | L16: =5.150809*0.0328767123287671 -> 0.16934167 | S16: 0.079533 | V16: 70 | W16: 0 | Z16: SELLO DE FECHA Y HORA
A17: NATURGY | B17: RESIDENCIAL | C17: GAS | D17: POR USO GAS | E17: RL.2 | L17: =9.149802*0.0328767123287671 -> 0.30081541 | S17: 0.077434 | V17: 70 | W17: 0 | Z17: SELLO DE FECHA Y HORA
A18: NATURGY | B18: RESIDENCIAL | C18: GAS | D18: POR USO GAS | E18: RL.3 | L18: =19.759738*0.0328767123287671 -> 0.64963522 | S18: 0.073993 | V18: 70 | W18: 0 | Z18: SELLO DE FECHA Y HORA
A19: NATURGY | B19: PYMES | C19: GAS | D19: PLAN COMPROMISO GAS | E19: RL.1 | L19: =+'Naturgy Pymes'!F66 -> 0.080382093 | S19: =+'Naturgy Pymes'!H66 -> 0.060064 | V19: SEGÚN TABLA CONSUMO | W19: 12M | Z19: SELLO DE FECHA Y HORA
A20: NATURGY | B20: PYMES | C20: GAS | D20: PLAN COMPROMISO GAS SUPRA | E20: RL.1 | L20: =+'Naturgy Pymes'!F66 -> 0.080382093 | S20: =+'Naturgy Pymes'!J66 -> 0.066164 | V20: SEGÚN TABLA CONSUMO | W20: 12M | Z20: SELLO DE FECHA Y HORA
A21: NATURGY | B21: PYMES | C21: GAS | D21: PLAN COMPROMISO GAS | E21: RL.2 | L21: =+'Naturgy Pymes'!F67 -> 0.21185583 | S21: =+'Naturgy Pymes'!H67 -> 0.057965 | V21: SEGÚN TABLA CONSUMO | W21: 12M | Z21: SELLO DE FECHA Y HORA
A22: NATURGY | B22: PYMES | C22: GAS | D22: PLAN COMPROMISO GAS SUPRA | E22: RL.2 | L22: =+'Naturgy Pymes'!F67 -> 0.21185583 | S22: =+'Naturgy Pymes'!J67 -> 0.064065 | V22: SEGÚN TABLA CONSUMO | W22: 12M | Z22: SELLO DE FECHA Y HORA
A23: NATURGY | B23: PYMES | C23: GAS | D23: PLAN COMPROMISO GAS | E23: RL.3 | L23: =+'Naturgy Pymes'!F68 -> 0.56067564 | S23: =+'Naturgy Pymes'!H68 -> 0.054525 | V23: SEGÚN TABLA CONSUMO | W23: 12M | Z23: SELLO DE FECHA Y HORA
A24: NATURGY | B24: PYMES | C24: GAS | D24: PLAN COMPROMISO GAS SUPRA | E24: RL.3 | L24: =+'Naturgy Pymes'!F68 -> 0.56067564 | S24: =+'Naturgy Pymes'!J68 -> 0.060625 | V24: SEGÚN TABLA CONSUMO | W24: 12M | Z24: SELLO DE FECHA Y HORA
A25: NATURGY | B25: PYMES | C25: GAS | D25: PLAN COMPROMISO GAS | E25: RL.4 | L25: =+'Naturgy Pymes'!F69 -> 1.3686556 | S25: =+'Naturgy Pymes'!H69 -> 0.058609 | V25: SEGÚN TABLA CONSUMO | W25: 12M | Z25: SELLO DE FECHA Y HORA
A26: NATURGY | B26: PYMES | C26: GAS | D26: PLAN COMPROMISO GAS SUPRA | E26: RL.4 | L26: =+'Naturgy Pymes'!F69 -> 1.3686556 | S26: =+'Naturgy Pymes'!J69 -> 0.064709 | V26: SEGÚN TABLA CONSUMO | W26: 12M | Z26: SELLO DE FECHA Y HORA
A27: NATURGY | B27: PYMES | C27: GAS | D27: PLAN COMPROMISO GAS | E27: RL.5 | L27: =+'Naturgy Pymes'!F70 -> 7.6385029 | S27: =+'Naturgy Pymes'!H70 -> 0.058546 | V27: SEGÚN TABLA CONSUMO | W27: 12M | Z27: SELLO DE FECHA Y HORA
A28: NATURGY | B28: PYMES | C28: GAS | D28: PLAN COMPROMISO GAS SUPRA | E28: RL.5 | L28: =+'Naturgy Pymes'!F69 -> 1.3686556 | S28: =+'Naturgy Pymes'!J69 -> 0.064709 | V28: SEGÚN TABLA CONSUMO | W28: 12M | Z28: SELLO DE FECHA Y HORA
A29: IBERDROLA | B29: RESIDENCIAL | C29: LUZ | D29: =+Iberdrola!B10 -> 2.0TD_2 Plan Exclusivo 15%TE/TP 1p | E29: 2.0 | F29: =+Iberdrola!U10 -> 0.11778082 | G29: =+Iberdrola!V10 -> 0.060246575 | M29: =+Iberdrola!I10 -> 0.207647 | N29: =+Iberdrola!I10 -> 0.207647 | O29: =+Iberdrola!I10 -> 0.207647 | T29: 0.15 | U29: =+Iberdrola!O10 -> 15% s/Te y Tp (+5% si PIH / PEH+ / UUEEn/ Pack Bienestar) | X29: =+Iberdrola!P10 -> 0.06 | Z29: SELLO DE FECHA Y HORA
A30: IBERDROLA | B30: RESIDENCIAL | C30: LUZ | D30: =+Iberdrola!B11 -> 2.0TD_2 Plan Exclusivo 15%TE/TP 3p | E30: 2.0 | F30: =+Iberdrola!U11 -> 0.11778082 | G30: =+Iberdrola!V11 -> 0.060246575 | M30: =+Iberdrola!I11 -> 0.2522 | N30: =+Iberdrola!I11 -> 0.2522 | O30: =+Iberdrola!I11 -> 0.2522 | T30: 0.15 | U30: =+Iberdrola!O11 -> 15% s/Te y Tp (+5% si PIH / PEH+ / UUEEn/ Pack Bienestar) | X30: =+Iberdrola!P11 -> 0.06 | Z30: SELLO DE FECHA Y HORA
A31: IBERDROLA | B31: RESIDENCIAL | C31: LUZ | D31: =+Iberdrola!B12 -> 2.0TD_2 Plan Especial plus 15%TE 1p | E31: 2.0 | F31: =+Iberdrola!U12 -> 0.10819178 | G31: =+Iberdrola!V12 -> 0.046547945 | M31: =+Iberdrola!I12 -> 0.14875 | N31: =+Iberdrola!I12 -> 0.14875 | O31: =+Iberdrola!I12 -> 0.14875 | T31: 0.15 | U31: =+Iberdrola!O12 -> 15% s/Te (+5% si PIH / PEH+ / UUEEn/ Pack Bienestar) | X31: =+Iberdrola!P12 -> 0.06 | Z31: SELLO DE FECHA Y HORA
A32: IBERDROLA | B32: RESIDENCIAL | C32: LUZ | D32: =+Iberdrola!B13 -> 2.0TD_2 Plan Hogar Especial | E32: 2.0 | F32: =+Iberdrola!U13 -> 0.084931507 | G32: =+Iberdrola!V13 -> 0.049287671 | M32: =+Iberdrola!I13 -> 0.191875 | N32: =+Iberdrola!I13 -> 0.191875 | O32: =+Iberdrola!I13 -> 0.191875 | T32: 0.15 | U32: =+Iberdrola!O13 -> 15% s/Te (+5% si PIH / PEH+ / UUEEn/ Pack Bienestar) | X32: =+Iberdrola!P13 -> 0.06 | Z32: SELLO DE FECHA Y HORA
A33: IBERDROLA | B33: RESIDENCIAL | C33: LUZ | D33: =+Iberdrola!B14 -> 2.0TD_2 Plan Estable | E33: 2.0 | F33: =+Iberdrola!U14 -> 0.10819178 | G33: =+Iberdrola!V14 -> 0.046547945 | M33: =+Iberdrola!I14 -> 0.174875 | N33: =+Iberdrola!I14 -> 0.174875 | O33: =+Iberdrola!I14 -> 0.174875 | T33: 0.15 | U33: =+Iberdrola!O14 -> 15% s/Te (+5% si PIH / PEH+ / UUEEn/ Pack Bienestar) | X33: =+Iberdrola!P14 -> 0.06 | Z33: SELLO DE FECHA Y HORA
A34: IBERDROLA | B34: RESIDENCIAL | C34: LUZ | D34: =+Iberdrola!B15 -> 2.0TD_2 Planazo | E34: 2.0 | F34: =+Iberdrola!U15 -> 0.10819178 | G34: =+Iberdrola!V15 -> 0.049287671 | M34: =+Iberdrola!I15 -> 0.191875 | N34: =+Iberdrola!I15 -> 0.191875 | O34: =+Iberdrola!I15 -> 0.191875 | T34: 0.15 | U34: =+Iberdrola!O15 -> 15% s/Te (+5% si PIH / PEH+ / UUEEn/ Pack Bienestar) + 100€ en conciertos | X34: =+Iberdrola!P15 -> 0.06 | Z34: SELLO DE FECHA Y HORA
A35: IBERDROLA | B35: RESIDENCIAL | C35: LUZ | D35: =+Iberdrola!B16 -> 2.0TD_2 Plan Más Ahorro | E35: 2.0 | F35: =+Iberdrola!U16 -> 0.10819178 | G35: =+Iberdrola!V16 -> 0.049287671 | M35: =+Iberdrola!I16 -> 0.171111 | N35: =+Iberdrola!I16 -> 0.171111 | O35: =+Iberdrola!I16 -> 0.171111 | T35: 0.1 | U35: =+Iberdrola!O16 -> 10% / 15% / 20% /25% / 30% Te (+5% si PIH / PEH+ / UUEEn/ Pack Bienestar) | X35: =+Iberdrola!P16 -> 0.06 | Z35: SELLO DE FECHA Y HORA
A36: IBERDROLA | B36: RESIDENCIAL | C36: LUZ | D36: =+Iberdrola!B17 -> 2.0TD_2 Plan Ahorro Inteligente 8 horas | E36: 2.0 | F36: =+Iberdrola!U17 -> 0.10819178 | G36: =+Iberdrola!V17 -> 0.049287671 | M36: =+Iberdrola!I17 -> 0.23526 | N36: =+Iberdrola!I17 -> 0.23526 | O36: =+Iberdrola!I17 -> 0.23526 | T36: 0.15 | U36: =+Iberdrola!O17 -> 15% s/Te (+5% si PIH / PEH+) | X36: =+Iberdrola!P17 -> 0.06 | Z36: SELLO DE FECHA Y HORA
A37: IBERDROLA | B37: RESIDENCIAL | C37: LUZ | D37: =+Iberdrola!B18 -> 2.0TD_2 Plan Ahorro Automático 100 | E37: 2.0 | F37: =+Iberdrola!U18 -> 0.10819178 | G37: =+Iberdrola!V18 -> 0.049287671 | M37: =+Iberdrola!I18 -> 0.217 | N37: =+Iberdrola!I18 -> 0.217 | O37: =+Iberdrola!I18 -> 0.217 | U37: =+Iberdrola!O18 -> 100€ (+20€ si PIH / PEH+/ PI / PEH ); 50% dos días de más consumo | X37: =+Iberdrola!P18 -> 0.06 | Z37: SELLO DE FECHA Y HORA
A38: IBERDROLA | B38: RESIDENCIAL | C38: LUZ | D38: =+Iberdrola!B19 -> 2.0TD_2 Plan Verano | E38: 2.0 | F38: =+Iberdrola!U19 -> 0.10819178 | G38: =+Iberdrola!V19 -> 0.049287671 | M38: =+Iberdrola!I19 -> 0.249822 | N38: =+Iberdrola!I19 -> 0.249822 | O38: =+Iberdrola!I19 -> 0.249822 | T38: 0.15 | U38: =+Iberdrola!O19 -> 15% s/Tp (+5% si PIH / PEH+ / UUEEn/ Pack Bienestar) | X38: =+Iberdrola!P19 -> 0.06 | Z38: SELLO DE FECHA Y HORA
A39: IBERDROLA | B39: RESIDENCIAL | C39: LUZ | D39: =+Iberdrola!B20 -> 2.0TD_2 Plan Estable Comunidades de Propietarios | E39: 2.0 | F39: =+Iberdrola!U20 -> 0.11641096 | G39: =+Iberdrola!V20 -> 0.052027397 | M39: =+Iberdrola!I20 -> 0.159131 | N39: =+Iberdrola!I20 -> 0.159131 | O39: =+Iberdrola!I20 -> 0.159131 | T39: 0.15 | U39: =+Iberdrola!O20 -> 15% s/Te (+5% si ACP) + 5% s/te 2año | X39: =+Iberdrola!P20 -> 0.06 | Z39: SELLO DE FECHA Y HORA
A40: IBERDROLA | B40: RESIDENCIAL | C40: LUZ | D40: =+Iberdrola!B21 -> 2.0TD_2 Plan Solar | E40: 2.0 | F40: =+Iberdrola!U21 -> 0.10819178 | G40: =+Iberdrola!V21 -> 0.049287671 | M40: =+Iberdrola!I21 -> 0.244 | N40: =+Iberdrola!I21 -> 0.244 | O40: =+Iberdrola!I21 -> 0.244 | U40: =+Iberdrola!O21 -> s/ dto | X40: =+Iberdrola!P21 -> 0.06 | Z40: SELLO DE FECHA Y HORA
...

Sheet Naturgy Pymes
B4: ELECTRICIDAD
C6: PLAN FIJO LUZ 24h (E0008) | L6: M | S6: B | Z6: A
L7: Plan Fijo Luz 24h TÉRMINO ENERGÍA (€/kWh) | R7: PFL ONE | S7: Plan Fijo Luz 24h ONE TÉRMINO ENERGÍA (€/kWh) | Y7: PFL SUPRA | Z7: Plan Fijo Luz 24h SUPRA TÉRMINO ENERGÍA (€/kWh)
E8: Consumo hasta: (kWh/año) | F8: P. TÉRMINO POTENCIA (€/kW.día)
F9: P1 | G9: P2 | H9: P3 | I9: P4 | J9: P5 | K9: P6 | L9: P1 | M9: P2 | N9: P3 | O9: P4 | P9: P5 | Q9: P6 | S9: P1 | T9: P2 | U9: P3 | V9: P4 | W9: P5 | X9: P6 | Z9: P1 | AA9: P2 | AB9: P3 | AC9: P4 | AD9: P5 | AE9: P6
A10: E000820TDM | B10: E0008 | C10: 20TD | D10: Plan Fijo Luz 24h 2.0 | E10: 9999999999 | F10: 0.12297298 | G10: 0.043976022 | L10: 0.136171 | R10: E000820TDB | S10: 0.120671 | Y10: E000820TDA | Z10: 0.149171 | AF10: E0008PFL ONE19999999999 | AG10: E0008PFL SUPRA19999999999
C13: PLAN FIJO LUZ (E0009) | L13: M | S13: B | Z13: A
L14: Plan Fijo Luz TÉRMINO ENERGÍA (€/kWh) | R14: PFL ONE | S14: Plan Fijo Luz ONE TÉRMINO ENERGÍA (€/kWh) | Y14: PFL SUPRA | Z14: Plan Fijo Luz SUPRA TÉRMINO ENERGÍA (€/kWh)
E15: Consumo hasta: (kWh/año) | F15: P. TÉRMINO POTENCIA (€/kW.día)
F16: P1 | G16: P2 | H16: P3 | I16: P4 | J16: P5 | K16: P6 | L16: P1 | M16: P2 | N16: P3 | O16: P4 | P16: P5 | Q16: P6 | S16: P1 | T16: P2 | U16: P3 | V16: P4 | W16: P5 | X16: P6 | Z16: P1 | AA16: P2 | AB16: P3 | AC16: P4 | AD16: P5 | AE16: P6
A17: E000920TDM | B17: E0009 | C17: 20TD | D17: Plan Fijo Luz 2.0 TRIHORARIO | E17: 9999999999 | F17: 0.12297298 | G17: 0.043976022 | L17: 0.206464 | M17: 0.133311 | N17: 0.097973 | R17: E000920TDB | S17: 0.190964 | T17: 0.117811 | U17: 0.082473 | Y17: E000920TDA | Z17: 0.219465 | AA17: 0.146312 | AB17: 0.110973 | AF17: E0009PFL ONE19999999999 | AG17: E0009PFL SUPRA19999999999
A18: E000930TDM | B18: E0009 | C18: 30TD | D18: Plan Fijo Luz 3.0 | E18: 9999999999 | F18: 0.057927649 | G18: 0.031189775 | H18: 0.014378597 | I18: 0.012747912 | J18: 0.0089877041 | K18: 0.0060519452 | L18: 0.195993 | M18: 0.170414 | N18: 0.147424 | O18: 0.133736 | P18: 0.127043 | Q18: 0.119208 | R18: E000930TDB | S18: 0.183593 | T18: 0.158014 | U18: 0.134925 | V18: 0.121236 | W18: 0.114444 | X18: 0.106808 | Y18: E000930TDA | Z18: 0.215493 | AA18: 0.189914 | AB18: 0.166925 | AC18: 0.153235 | AD18: 0.146543 | AE18: 0.138708 | AF18: E0009PFL ONE19999999999 | AG18: E0009PFL SUPRA19999999999
A19: E000961TDM | B19: E0009 | C19: 61TD | D19: Plan Fijo Luz 6.1 | E19: 9999999999 | F19: 0.081083211 | G19: 0.042506038 | H19: 0.018635277 | I19: 0.014777622 | J19: 0.0058222356 | K19: 0.002751189 | L19: 0.170106 | M19: 0.149355 | N19: 0.133961 | O19: 0.124135 | P19: 0.117561 | Q19: 0.111182 | R19: E000961TDB | S19: 0.158307 | T19: 0.137456 | U19: 0.122062 | V19: 0.112235 | W19: 0.105661 | X19: 0.099383 | Y19: E000961TDA | Z19: 0.189606 | AA19: 0.168856 | AB19: 0.153461 | AC19: 0.143635 | AD19: 0.13706 | AE19: 0.130683 | AF19: E0009PFL ONE19999999999 | AG19: E0009PFL SUPRA19999999999
Z20: 0.11 | AA20: 0.13 | AB20: 0.13 | AC20: 0.14 | AD20: 0.05 | AE20: 0.44
C21: PLAN FIJO LUZ ECO (E0010) | L21: M | S21: B | Z21: A
C22: 0.0094 | L22: Plan Fijo Luz ECO TÉRMINO ENERGÍA (€/kWh) | R22: PFL ONE | S22: Plan Fijo Luz ECO ONE TÉRMINO ENERGÍA (€/kWh) | Y22: PFL SUPRA | Z22: Plan Fijo Luz ECO SUPRA TÉRMINO ENERGÍA (€/kWh)
E23: Consumo hasta: (kWh/año) | F23: P. TÉRMINO POTENCIA (€/kW.día)
F24: P1 | G24: P2 | H24: P3 | I24: P4 | J24: P5 | K24: P6 | L24: P1 | M24: P2 | N24: P3 | O24: P4 | P24: P5 | Q24: P6 | S24: P1 | T24: P2 | U24: P3 | V24: P4 | W24: P5 | X24: P6 | Z24: P1 | AA24: P2 | AB24: P3 | AC24: P4 | AD24: P5 | AE24: P6
A25: E001020TDM | B25: E0010 | C25: 20TD | D25: Plan Fijo Luz ECO 2.0 TRIHORARIO | E25: 9999999999 | F25: 0.12297298 | G25: 0.043976022 | L25: 0.209975 | M25: 0.136822 | N25: 0.101483 | R25: E001020TDB | S25: 0.194475 | T25: 0.121322 | U25: 0.085983 | Y25: E001020TDA | Z25: 0.222975 | AA25: 0.149822 | AB25: 0.114483 | AF25: E0010PFL ONE19999999999 | AG25: E0010PFL SUPRA19999999999
A26: E001030TDM | B26: E0010 | C26: 30TD | D26: Plan Fijo Luz ECO 3.0 | E26: 9999999999 | F26: 0.057927649 | G26: 0.031189775 | H26: 0.014378597 | I26: 0.012747912 | J26: 0.0089877041 | K26: 0.0060519452 | L26: 0.199503 | M26: 0.173924 | N26: 0.150935 | O26: 0.137245 | P26: 0.130553 | Q26: 0.122718 | R26: E001030TDB | S26: 0.187103 | T26: 0.161524 | U26: 0.138435 | V26: 0.124746 | W26: 0.117954 | X26: 0.110318 | Y26: E001030TDA | Z26: 0.219003 | AA26: 0.193424 | AB26: 0.170435 | AC26: 0.156745 | AD26: 0.150053 | AE26: 0.142218 | AF26: E0010PFL ONE19999999999 | AG26: E0010PFL SUPRA19999999999
A27: E001061TDM | B27: E0010 | C27: 61TD | D27: Plan Fijo Luz ECO 6.1 | E27: 9999999999 | F27: 0.081083211 | G27: 0.042506038 | H27: 0.018635277 | I27: 0.014777622 | J27: 0.0058222356 | K27: 0.002751189 | L27: 0.173616 | M27: 0.152866 | N27: 0.137471 | O27: 0.127645 | P27: 0.12107 | Q27: 0.114693 | R27: E001061TDB | S27: 0.161817 | T27: 0.140966 | U27: 0.125572 | V27: 0.115745 | W27: 0.109171 | X27: 0.102893 | Y27: E001061TDA | Z27: 0.193116 | AA27: 0.172366 | AB27: 0.156971 | AC27: 0.147145 | AD27: 0.14057 | AE27: 0.134193 | AF27: E0010PFL ONE19999999999 | AG27: E0010PFL SUPRA19999999999
C29: PLAN VARIABLE LUZ (E0013)
L30: Plan Variable Luz TÉRMINO ENERGÍA (€/kWh) | R30: PNM ONE | S30: Plan Variable Luz ONE TÉRMINO ENERGÍA (€/kWh) | Y30: PFL SUPRA | Z30: Plan Variable Luz SUPRA TÉRMINO ENERGÍA (€/kWh)
E31: Consumo hasta: (kWh/año) | F31: P. TÉRMINO POTENCIA (€/kW.día)
F32: P1 | G32: P2 | H32: P3 | I32: P4 | J32: P5 | K32: P6 | L32: P1 | M32: P2 | N32: P3 | O32: P4 | P32: P5 | Q32: P6 | S32: P1 | T32: P2 | U32: P3 | V32: P4 | W32: P5 | X32: P6 | Z32: P1 | AA32: P2 | AB32: P3 | AC32: P4 | AD32: P5 | AE32: P6
A33: 20TD | B33: 42053 | C33: 2.0TD | D33: Plan Variable Luz 2.0 | E33: 9999999999 | F33: 0.079327162 | G33: 0.0054121205 | L33: 0.258866 | M33: 0.183799 | N33: 0.139187 | S33: 0.243366 | T33: 0.168299 | U33: 0.123687 | Y33: -6 | Z33: 0.264866 | AA33: 0.189799 | AB33: 0.145187
A34: 30TD | B34: 42055 | C34: 3.0TD | D34: Plan Variable Luz 3.0 | E34: 9999999999 | F34: 0.056283827 | G34: 0.029545995 | H34: 0.012734797 | I34: 0.01110411 | J34: 0.0073438849 | K34: 0.0044081041 | L34: 0.222898 | M34: 0.196761 | Q34: 0.141847 | S34: 0.207398 | T34: 0.181261 | X34: 0.126347 | Z34: 0.228898 | AA34: 0.202761 | AE34: 0.147847
A35: 61TD | B35: 42057 | C35: 6.1TD | D35: Plan Variable Luz 6X | E35: 9999999999 | F35: 0.0810832 | G35: 0.042506052 | H35: 0.01863529 | I35: 0.014777614 | J35: 0.0058222274 | K35: 0.0027511808 | L35: 0.194917 | M35: 0.172743 | Q35: 0.130985 | S35: 0.179417 | T35: 0.157243 | X35: 0.115485 | Z35: 0.200917 | AA35: 0.178743 | AE35: 0.136985
C38: TEMPORADA/OBRA
E40: Consumo hasta: (kWh/año) | F40: P. TÉRMINO POTENCIA (€/kW.día) | L40: P. TÉRMINO ENERGÍA (€/kWh)
F41: P1 | G41: P2 | H41: P3 | I41: P4 | J41: P5 | K41: P6 | L41: P1 | M41: P2 | N41: P3 | O41: P4 | P41: P5 | Q41: P6
A42: 4200919999999999 | B42: 42009 | C42: 2.0TD | D42: Contrato Temporada/Obra 2.0TD | E42: 9999999999 | F42: #N/A | G42: #N/A | H42: #N/A | I42: #N/A | J42: #N/A | K42: #N/A | L42: #N/A | M42: #N/A | N42: #N/A | O42: #N/A | P42: #N/A | Q42: #N/A
A43: 4202319999999999 | B43: 42023 | C43: 2.0TD Trihoraria | D43: Contrato Temporada/Obra Trihorario 2.0TD | E43: 9999999999 | F43: #N/A | G43: #N/A | H43: #N/A | I43: #N/A | J43: #N/A | K43: #N/A | L43: #N/A | M43: #N/A | N43: #N/A | O43: #N/A | P43: #N/A | Q43: #N/A
A44: 4203819999999999 | B44: 42038 | C44: 3.0TD | D44: Contrato Temporada/Obra 3.0TD | E44: 9999999999 | F44: #N/A | G44: #N/A | H44: #N/A | I44: #N/A | J44: #N/A | K44: #N/A | L44: #N/A | M44: #N/A | N44: #N/A | O44: #N/A | P44: #N/A | Q44: #N/A
A45: 4205019999999999 | B45: 42050 | C45: 6.1TD | D45: Contrato Temporada/Obra 6.XTD | E45: 9999999999 | F45: #N/A | G45: #N/A | H45: #N/A | I45: #N/A | J45: #N/A | K45: #N/A | L45: #N/A | M45: #N/A | N45: #N/A | O45: #N/A | P45: #N/A | Q45: #N/A
B48: GAS
C50: PLAN VARIABLE GAS (G0009) | G50: PLAN VARIABLE GAS SUPRA | I50: PLAN VARIABLE GAS | K50: PLAN VARIABLE GAS ONE
G52: Sin Dto | H52: A | I52: Dto 3€/MWh TV | K52: Dto 8€/MWh TV
E53: Consumo hasta: (kWh/año) | F53: PRECIO TÉRMINO FIJO (€/día/cliente) | H53: PRECIO TÉRMINO VARIABLE (€/kWh) | J53: PRECIO TÉRMINO VARIABLE (€/kWh) | L53: PRECIO TÉRMINO VARIABLE (€/kWh)
A55: G0009RL.1A | B55: G0009 | C55: RL.1 | D55: PLAN VARIABLE GAS MENSUAL | E55: 5000 | F55: 0.080382093 | G55: 0 | H55: 0.056145 | I55: 3 | J55: 0.053145 | K55: 8 | L55: 0.048145
...

Sheet Iberdrola
B2: PRODUCTOS | C2: TERMINO DE POTENCIA (€/kW año) | I2: TERMINO DE ENERGIA (€/kWh) | O2: DESCUENTO | P2: Precio Excedentes | Q2: DURACION | R2: FACTURA ELECT. | S2: ENERGIA VERDE | T2: CANAL PRESEN | U2: TERMINO DE POTENCIA (€/kW dia)
C3: P1 | D3: P2 | E3: P3 | F3: P4 | G3: P5 | H3: P6 | I3: P1 | J3: P2 | K3: P3 | L3: P4 | M3: P5 | N3: P6 | U3: P1 | V3: P2
C4: Punta | D4: Valle | I4: Punta | J4: Llano | K4: Valle | U4: Punta | V4: Valle
I5: No Prom. | J5: Prom. | O5: % | P5: €/Kwh | Q5: (Precio/Dto) | R5: (Obligat.) | S5: (GdO) | T5: (S/N) | U5: €/kWdía | V5: €/kWdía
C6: 1 | D6: 2 | E6: 3 | F6: 4 | G6: 5 | H6: 6 | I6: 7 | J6: 8 | K6: 9 | L6: 10 | M6: 11 | N6: 12
B8: ELECTRICIDAD - 2.0TD [P1 =< 15kW] Baja Tensión
B9: 2.0TD _ 2 P1 <= 10kW
B10: 2.0TD_2 Plan Exclusivo 15%TE/TP 1p | C10: 42.99 | D10: 21.99 | I10: 0.207647 | O10: 15% s/Te y Tp (+5% si PIH / PEH+ / UUEEn/ Pack Bienestar) | P10: 0.06 | Q10: 12m | R10: N | S10: N | T10: S | U10: 0.11778082 | V10: 0.060246575
B11: 2.0TD_2 Plan Exclusivo 15%TE/TP 3p | C11: 42.99 | D11: 21.99 | I11: 0.2522 | J11: 0.2107 | K11: 0.1828 | O11: 15% s/Te y Tp (+5% si PIH / PEH+ / UUEEn/ Pack Bienestar) | P11: 0.06 | Q11: 12m | R11: N | S11: N | T11: S | U11: 0.11778082 | V11: 0.060246575
B12: 2.0TD_2 Plan Especial plus 15%TE 1p | C12: 39.49 | D12: 16.99 | I12: 0.14875 | O12: 15% s/Te (+5% si PIH / PEH+ / UUEEn/ Pack Bienestar) | P12: 0.06 | Q12: 12m | R12: N | S12: N | T12: S | U12: 0.10819178 | V12: 0.046547945
B13: 2.0TD_2 Plan Hogar Especial | C13: 31 | D13: 17.99 | I13: 0.191875 | O13: 15% s/Te (+5% si PIH / PEH+ / UUEEn/ Pack Bienestar) | P13: 0.06 | Q13: 36m / 12m | R13: N | S13: N | T13: S | U13: 0.084931507 | V13: 0.049287671
B14: 2.0TD_2 Plan Estable | C14: 39.49 | D14: 16.99 | I14: 0.174875 | O14: 15% s/Te (+5% si PIH / PEH+ / UUEEn/ Pack Bienestar) | P14: 0.06 | Q14: 60m / 12m | R14: S | S14: S | T14: S | U14: 0.10819178 | V14: 0.046547945
B15: 2.0TD_2 Planazo | C15: 39.49 | D15: 17.99 | I15: 0.191875 | O15: 15% s/Te (+5% si PIH / PEH+ / UUEEn/ Pack Bienestar) + 100€ en conciertos | P15: 0.06 | Q15: 60m / 12m | R15: S | S15: S | T15: S | U15: 0.10819178 | V15: 0.049287671
B16: 2.0TD_2 Plan Más Ahorro | C16: 39.49 | D16: 17.99 | I16: 0.171111 | O16: 10% / 15% / 20% /25% / 30% Te (+5% si PIH / PEH+ / UUEEn/ Pack Bienestar) | P16: 0.06 | Q16: 60m / 12m* | R16: S | S16: S | T16: S | U16: 0.10819178 | V16: 0.049287671
B17: 2.0TD_2 Plan Ahorro Inteligente 8 horas | C17: 39.49 | D17: 17.99 | I17: 0.23526 | J17: 0.11763 | O17: 15% s/Te (+5% si PIH / PEH+) | P17: 0.06 | Q17: 60m / 24m | R17: S | S17: S | T17: S | U17: 0.10819178 | V17: 0.049287671
B18: 2.0TD_2 Plan Ahorro Automático 100 | C18: 39.49 | D18: 17.99 | I18: 0.217 | O18: 100€ (+20€ si PIH / PEH+/ PI / PEH ); 50% dos días de más consumo | P18: 0.06 | Q18: 60m / 12m | R18: S | S18: S | T18: S | U18: 0.10819178 | V18: 0.049287671
B19: 2.0TD_2 Plan Verano | C19: 39.49 | D19: 17.99 | I19: 0.249822 | J19: 0.124911 | O19: 15% s/Tp (+5% si PIH / PEH+ / UUEEn/ Pack Bienestar) | P19: 0.06 | Q19: 60m / 12m | R19: S | S19: S | T19: S | U19: 0.10819178 | V19: 0.049287671
B20: 2.0TD_2 Plan Estable Comunidades de Propietarios | C20: 42.49 | D20: 18.99 | I20: 0.159131 | O20: 15% s/Te (+5% si ACP) + 5% s/te 2año | P20: 0.06 | Q20: 24m | R20: S | S20: S | T20: S | U20: 0.11641096 | V20: 0.052027397
B21: 2.0TD_2 Plan Solar | C21: 39.49 | D21: 17.99 | I21: 0.244 | J21: 0.122 | O21: s/ dto | P21: 0.06 | Q21: 12m | R21: S | S21: S | T21: S | U21: 0.10819178 | V21: 0.049287671
B22: 2.0TD_2 Plan Recarga Inteligente | C22: 39.49 | D22: 17.99 | I22: 0.149999 | O22: s/ dto | P22: 0.06 | Q22: 12m | R22: S | S22: S | T22: S | U22: 0.10819178 | V22: 0.049287671
B23: 2.0TD_2 Impulsa 24h | C23: 42.49 | D23: 16.99 | I23: 0.1732 | O23: 20% s/Te (+5% si PIH / PEH+ / UUEEn/ Pack Bienestar) | P23: 0.06 | Q23: 12m | R23: S | S23: N | T23: S | U23: 0.11641096 | V23: 0.046547945
B24: 2.0TD_2 Plan OMIE | C24: 26.93055 | D24: 0.697588 | I24: 0.015 | O24: s/ dto (únicamente para fidelización) | P24: PVPC | Q24: 12m | R24: N | S24: N | T24: S | U24: 0.073782329 | V24: 0.0019112
B25: 2.0TD_2 Plan OMIE Comunidades | C25: 26.93055 | D25: 0.697588 | I25: 0.03 | O25: s/ dto | P25: PVPC | Q25: 12m | R25: N | S25: N | T25: S | U25: 0.073782329 | V25: 0.0019112
B26: 2.0TD _ 3 P1 > 10kW
B27: 2.0TD_3 Plan Exclusivo 15%TE/TP 1p | C27: 42.99 | D27: 21.99 | I27: 0.207647 | O27: 15% s/Te y Tp (+5% si PIH / PEH+ / UUEEn/ Pack Bienestar) | P27: 0.06 | Q27: 12m | R27: N | S27: N | T27: S | U27: 0.11778082 | V27: 0.060246575
B28: 2.0TD_3 Plan Exclusivo 15%TE/TP 3p | C28: 42.99 | D28: 21.99 | I28: 0.2481 | J28: 0.2148 | K28: 0.2045 | O28: 15% s/Te y Tp (+5% si PIH / PEH+ / UUEEn/ Pack Bienestar) | P28: 0.06 | Q28: 12m | R28: N | S28: N | T28: S | U28: 0.11778082 | V28: 0.060246575
B29: 2.0TD_3 Plan Especial plus 15%TE 1p | C29: 39.49 | D29: 16.99 | I29: 0.15375 | O29: 15% s/Te (+5% si PIH / PEH+ / UUEEn/ Pack Bienestar) | P29: 0.06 | Q29: 12m | R29: N | S29: N | T29: S | U29: 0.10819178 | V29: 0.046547945
B30: 2.0TD_3 Plan Hogar Especial | C30: 31 | D30: 17.99 | I30: 0.196875 | O30: 15% s/Te (+5% si PIH / PEH+ / UUEEn/ Pack Bienestar) | P30: 0.06 | Q30: 36m / 12m | R30: N | S30: N | T30: S | U30: 0.084931507 | V30: 0.049287671
B31: 2.0TD_3 Plan Estable | C31: 39.49 | D31: 16.99 | I31: 0.174875 | O31: 15% s/Te (+5% si PIH / PEH+ / UUEEn/ Pack Bienestar) | P31: 0.06 | Q31: 60m / 12m | R31: S | S31: S | T31: S | U31: 0.10819178 | V31: 0.046547945
B32: 2.0TD_3 Planazo | C32: 39.49 | D32: 17.99 | I32: 0.191875 | O32: 15% s/Te (+5% si PIH / PEH+ / UUEEn/ Pack Bienestar) + 100€ en conciertos | P32: 0.06 | Q32: 60m / 12m | R32: S | S32: S | T32: S | U32: 0.10819178 | V32: 0.049287671
B33: 2.0TD_3 Plan Más Ahorro | C33: 39.49 | D33: 17.99 | I33: 0.181111 | O33: 10% / 15% / 20% /25% / 30% Te (+5% si PIH / PEH+ / UUEEn/ Pack Bienestar) | P33: 0.06 | Q33: 60m / 12m | R33: S | S33: S | T33: S | U33: 0.10819178 | V33: 0.049287671
B34: 2.0TD_3 Plan Ahorro Inteligente 8 horas | C34: 39.49 | D34: 17.99 | I34: 0.24526 | J34: 0.12263 | O34: 15% s/Te (+5% si PIH / PEH+ / UUEEn/ Pack Bienestar) | P34: 0.06 | Q34: 60m / 24m | R34: S | S34: S | T34: S | U34: 0.10819178 | V34: 0.049287671
B35: 2.0TD_3 Plan Ahorro Automático 100 | C35: 39.49 | D35: 17.99 | I35: 0.217 | O35: 100€ (+20€ si PIH / PEH+/ PI / PEH ) | P35: 0.06 | Q35: 60m / 12m | R35: S | S35: S | T35: S | U35: 0.10819178 | V35: 0.049287671
B36: 2.0TD_3 Plan Verano | C36: 39.49 | D36: 17.99 | I36: 0.249822 | J36: 0.124911 | O36: 15% s/Tp (+5% si PIH / PEH+ / UUEEn/ Pack Bienestar) | P36: 0.06 | Q36: 60m / 12m | R36: S | S36: S | T36: S | U36: 0.10819178 | V36: 0.049287671
B37: 2.0TD_3 Plan Estable Comunidades de Propietarios | C37: 42.49 | D37: 18.99 | I37: 0.159131 | O37: 15% s/Te (+5% si ACP) + 5% s/te 2año | P37: 0.06 | Q37: 24m | R37: S | S37: S | T37: S | U37: 0.11641096 | V37: 0.052027397
B38: 2.0TD_3 Plan Solar | C38: 39.49 | D38: 17.99 | I38: 0.244 | J38: 0.122 | O38: s/ dto | P38: 0.06 | Q38: 12m | R38: S | S38: S | T38: S | U38: 0.10819178 | V38: 0.049287671
B39: 2.0TD_3 Plan Recarga Inteligente | C39: 39.49 | D39: 17.99 | I39: 0.149999 | O39: s/ dto | P39: 0.06 | Q39: 12m | R39: S | S39: S | T39: S | U39: 0.10819178 | V39: 0.049287671
B40: 2.0TD_3 Impulsa 24h | C40: 42.49 | D40: 16.99 | I40: 0.1732 | O40: 20% s/Te (+5% si PIH / PEH+ / UUEEn/ Pack Bienestar) | P40: 0.06 | Q40: 12m | R40: S | S40: N | T40: S | U40: 0.11641096 | V40: 0.046547945
B41: 2.0TD_3 Plan OMIE | C41: 26.93055 | D41: 0.697588 | I41: 0.03 | O41: s/ dto | P41: PVPC | Q41: 12m | R41: N | S41: N | T41: S | U41: 0.073782329 | V41: 0.0019112
B42: 2.0TD_3 Plan OMIE Comunidades | C42: 26.93055 | D42: 0.697588 | I42: 0.03 | O42: s/ dto | P42: PVPC | Q42: 12m | R42: N | S42: N | T42: S | U42: 0.073782329 | V42: 0.0019112
...

Sheet AXPO
K4: 1P PLUS (Periodo Único)
A7: SUPER (N1) | I7: ESTANDAR (N2) | Q7: EXTRA (N3)
A9: Peninsula | B9: Precio Término de Energía (€/kWh) Precio Término de potencia (€/kWaño) Consumos 0-3.000.000 kWh/año | I9: Peninsula | J9: Precio Término de Energía (€/kWh) Precio Término de potencia (€/kWaño) Consumos 0-3.000.000 kWh/año | Q9: Peninsula | R9: Precio Término de Energía (€/kWh) Precio Término de potencia (€/kWaño) Consumos 0-3.000.000 kWh/año
A10: Tarifa | B10: P1 | C10: P2 | D10: P3 | E10: P4 | F10: P5 | G10: P6 | I10: Tarifa | J10: P1 | K10: P2 | L10: P3 | M10: P4 | N10: P5 | O10: P6 | Q10: Tarifa | R10: P1 | S10: P2 | T10: P3 | U10: P4 | V10: P5 | W10: P6
A11: 2.0TD | B11: 0.143997 | C11: 0.143997 | D11: 0.143997 | I11: 2.0TD | J11: 0.138921 | K11: 0.138921 | L11: 0.138921 | Q11: 2.0TD | R11: 0.133845 | S11: 0.133845 | T11: 0.133845
A12: 3.0TD | B12: 0.123864 | C12: 0.123864 | D12: 0.123864 | E12: 0.123864 | F12: 0.123864 | G12: 0.123864 | I12: 3.0TD | J12: 0.118788 | K12: 0.118788 | L12: 0.118788 | M12: 0.118788 | N12: 0.118788 | O12: 0.118788 | Q12: 3.0TD | R12: 0.113712 | S12: 0.113712 | T12: 0.113712 | U12: 0.113712 | V12: 0.113712 | W12: 0.113712
I15: POTENCIAS
A18: Precio Término de potencia (€/kWaño) Consumos 0-50.000 kWh/año | I18: Precio Término de potencia (€/kWaño) Consumos 0-50.000 kWh/año | Q18: Precio Término de potencia (€/kWaño) Consumos 0-50.000 kWh/año
A19: Tarifa | B19: P1 | C19: P2 | D19: P3 | E19: P4 | F19: P5 | G19: P6 | I19: Tarifa | J19: P1 | K19: P2 | L19: P3 | M19: P4 | N19: P5 | O19: P6 | Q19: Tarifa | R19: P1 | S19: P2 | T19: P3 | U19: P4 | V19: P5 | W19: P6
A20: 2.0TD | B20: 39.704413 | C20: 21.725423 | I20: 2.0TD | J20: 37.704413 | K20: 19.725423 | Q20: 2.0TD | R20: 34.204413 | S20: 19.725423
A21: 3.0TD | B21: 24.876927 | C21: 15.117621 | D21: 8.981534 | E21: 12.386333 | F21: 14.013851 | G21: 14.442287 | I21: 3.0TD | J21: 23.376927 | K21: 13.617621 | L21: 7.581534 | M21: 11.386333 | N21: 13.013851 | O21: 13.442287 | Q21: 3.0TD | R21: 23.376927 | S21: 13.617621 | T21: 7.481534 | U21: 10.386333 | V21: 10.513851 | W21: 9.942287
K26: ESTABLE
A29: SUPER (N1) | I29: ESTANDAR (N2) | Q29: EXTRA (N3)
A31: Peninsula | B31: Precio Término de Energía (€/kWh) Precio Término de potencia (€/kWaño) Consumos 0-3.000.000 kWh/año | I31: Peninsula | J31: Precio Término de Energía (€/kWh) Precio Término de potencia (€/kWaño) Consumos 0-3.000.000 kWh/año | Q31: Peninsula | R31: Precio Término de Energía (€/kWh) Precio Término de potencia (€/kWaño) Consumos 0-3.000.000 kWh/año
A32: Tarifa | B32: P1 | C32: P2 | D32: P3 | E32: P4 | F32: P5 | G32: P6 | I32: Tarifa | J32: P1 | K32: P2 | L32: P3 | M32: P4 | N32: P5 | O32: P6 | Q32: Tarifa | R32: P1 | S32: P2 | T32: P3 | U32: P4 | V32: P5 | W32: P6
A33: 2.0TD | B33: 0.225997 | C33: 0.155052 | D33: 0.128089 | I33: 2.0TD | J33: 0.214179 | K33: 0.143234 | L33: 0.116272 | Q33: 2.0TD | R33: 0.207905 | S33: 0.13696 | T33: 0.109998
A34: 3.0TD | B34: 0.202053 | C34: 0.17247 | D34: 0.140552 | E34: 0.119471 | F34: 0.106175 | G34: 0.124617 | I34: 3.0TD | J34: 0.190236 | K34: 0.160653 | L34: 0.128735 | M34: 0.107653 | N34: 0.094358 | O34: 0.1128 | Q34: 3.0TD | R34: 0.183962 | S34: 0.154378 | T34: 0.122461 | U34: 0.101379 | V34: 0.088084 | W34: 0.106526
A35: 6.1TD | B35: 0.174387 | C35: 0.15142 | D35: 0.127164 | E35: 0.111237 | F35: 0.100046 | G35: 0.121011 | I35: 6.1TD | J35: 0.162569 | K35: 0.139603 | L35: 0.115347 | M35: 0.09942 | N35: 0.088228 | O35: 0.109193 | Q35: 6.1TD | R35: 0.156295 | S35: 0.133329 | T35: 0.109073 | U35: 0.093146 | V35: 0.081954 | W35: 0.102919
A38: Baleares | B38: Precio Término de Energía (€/kWh) Precio Término de potencia (€/kWaño) Consumos 0-3.000.000 kWh/año | I38: Baleares | J38: Precio Término de Energía (€/kWh) Precio Término de potencia (€/kWaño) Consumos 0-3.000.000 kWh/año | Q38: Baleares | R38: Precio Término de Energía (€/kWh) Precio Término de potencia (€/kWaño) Consumos 0-3.000.000 kWh/año
A39: Tarifa | B39: P1 | C39: P2 | D39: P3 | E39: P4 | F39: P5 | G39: P6 | I39: Tarifa | J39: P1 | K39: P2 | L39: P3 | M39: P4 | N39: P5 | O39: P6 | Q39: Tarifa | R39: P1 | S39: P2 | T39: P3 | U39: P4 | V39: P5 | W39: P6
A40: 2.0TD | B40: 0.228487 | C40: 0.154317 | D40: 0.124392 | I40: 2.0TD | J40: 0.21667 | K40: 0.1425 | L40: 0.112575 | Q40: 2.0TD | R40: 0.210396 | S40: 0.136226 | T40: 0.106301
A41: 3.0TD | B41: 0.177014 | C41: 0.161456 | D41: 0.150842 | E41: 0.138032 | F41: 0.125921 | G41: 0.125213 | I41: 3.0TD | J41: 0.165197 | K41: 0.149638 | L41: 0.139025 | M41: 0.126215 | N41: 0.114104 | O41: 0.113396 | Q41: 3.0TD | R41: 0.158923 | S41: 0.143364 | T41: 0.132751 | U41: 0.119941 | V41: 0.10783 | W41: 0.107122
A42: 6.1TD | B42: 0.151157 | C42: 0.140142 | D42: 0.136471 | E42: 0.126723 | F42: 0.115808 | G42: 0.115573 | I42: 6.1TD | J42: 0.13934 | K42: 0.128325 | L42: 0.124654 | M42: 0.114906 | N42: 0.103991 | O42: 0.103755 | Q42: 6.1TD | R42: 0.133065 | S42: 0.122051 | T42: 0.11838 | U42: 0.108632 | V42: 0.097717 | W42: 0.097481
A45: Canarias | B45: Precio Término de Energía (€/kWh) Precio Término de potencia (€/kWaño) Consumos 0-3.000.000 kWh/año | I45: Canarias | J45: Precio Término de Energía (€/kWh) Precio Término de potencia (€/kWaño) Consumos 0-3.000.000 kWh/año | Q45: Canarias | R45: Precio Término de Energía (€/kWh) Precio Término de potencia (€/kWaño) Consumos 0-3.000.000 kWh/año
A46: Tarifa | B46: P1 | C46: P2 | D46: P3 | E46: P4 | F46: P5 | G46: P6 | I46: Tarifa | J46: P1 | K46: P2 | L46: P3 | M46: P4 | N46: P5 | O46: P6 | Q46: Tarifa | R46: P1 | S46: P2 | T46: P3 | U46: P4 | V46: P5 | W46: P6
A47: 2.0TD | B47: 0.228487 | C47: 0.154317 | D47: 0.124392 | I47: 2.0TD | J47: 0.21667 | K47: 0.1425 | L47: 0.112575 | Q47: 2.0TD | R47: 0.210396 | S47: 0.136226 | T47: 0.106301
A48: 3.0TD | B48: 0.18581 | C48: 0.174827 | D48: 0.158637 | E48: 0.117853 | F48: 0.104941 | G48: 0.125213 | I48: 3.0TD | J48: 0.173993 | K48: 0.16301 | L48: 0.14682 | M48: 0.106036 | N48: 0.093123 | O48: 0.113396 | Q48: 3.0TD | R48: 0.167719 | S48: 0.156736 | T48: 0.140546 | U48: 0.099762 | V48: 0.086849 | W48: 0.107122
A49: 6.1TD | B49: 0.159091 | C49: 0.152228 | D49: 0.143661 | E49: 0.108212 | F49: 0.096658 | G49: 0.115573 | I49: 6.1TD | J49: 0.147274 | K49: 0.140411 | L49: 0.131843 | M49: 0.096394 | N49: 0.08484 | O49: 0.103755 | Q49: 6.1TD | R49: 0.141 | S49: 0.134137 | T49: 0.125569 | U49: 0.09012 | V49: 0.078566 | W49: 0.097481
I52: POTENCIAS
A54: Peninsula | I54: Peninsula | Q54: Peninsula
A55: Precio Término de potencia (€/kWaño) Consumos 0-3.000.000 kWh/año | I55: Precio Término de potencia (€/kWdía) Consumos 0-3.000.000 kWh/año | Q55: Precio Término de potencia (€/kWmes) Consumos 0-3.000.000 kWh/año
A56: Tarifa | B56: P1 | C56: P2 | D56: P3 | E56: P4 | F56: P5 | G56: P6 | I56: Tarifa | J56: P1 | K56: P2 | L56: P3 | M56: P4 | N56: P5 | O56: P6 | Q56: Tarifa | R56: P1 | S56: P2 | T56: P3 | U56: P4 | V56: P5 | W56: P6
A57: 2.0TD | B57: 27.704413 | C57: 0.725423 | I57: 2.0TD | J57: =B57/365 -> 0.075902501 | K57: =C57/365 -> 0.0019874603 | Q57: 2.0TD | R57: =B57/12 -> 2.3087011 | S57: =C57/12 -> 0.060451917
A58: 3.0TD | B58: 20.376927 | C58: 10.617621 | D58: 4.481534 | E58: 3.886333 | F58: 2.513851 | G58: 1.442287 | I58: 3.0TD | J58: =B58/365 -> 0.055827197 | K58: =C58/365 -> 0.029089373 | L58: =D58/365 -> 0.012278175 | M58: =E58/365 -> 0.010647488 | N58: =F58/365 -> 0.006887263 | O58: =G58/365 -> 0.0039514712 | Q58: 3.0TD | R58: =B58/12 -> 1.6980772 | S58: =C58/12 -> 0.88480175 | T58: =D58/12 -> 0.37346117 | U58: =E58/12 -> 0.32386108 | V58: =F58/12 -> 0.20948758 | W58: =G58/12 -> 0.12019058
A59: 6.1TD | B59: 29.595368 | C59: 15.514709 | D59: 6.801881 | E59: 5.393829 | F59: 2.125113 | G59: 1.004181 | I59: 6.1TD | J59: =B59/365 -> 0.0810832 | K59: =C59/365 -> 0.042506052 | L59: =D59/365 -> 0.01863529 | M59: =E59/365 -> 0.014777614 | N59: =F59/365 -> 0.0058222274 | O59: =G59/365 -> 0.0027511808 | Q59: 6.1TD | R59: =B59/12 -> 2.4662807 | S59: =C59/12 -> 1.2928924 | T59: =D59/12 -> 0.56682342 | U59: =E59/12 -> 0.44948575 | V59: =F59/12 -> 0.17709275 | W59: =G59/12 -> 0.08368175
A61: Baleares | I61: Baleares | Q61: Baleares
A62: Precio Término de potencia (€/kWaño) Consumos 0-3.000.000 kWh/año | I62: Precio Término de potencia (€/kWdía) Consumos 0-3.000.000 kWh/año | Q62: Precio Término de potencia (€/kWmes) Consumos 0-3.000.000 kWh/año
A63: Tarifa | B63: P1 | C63: P2 | D63: P3 | E63: P4 | F63: P5 | G63: P6 | I63: Tarifa | J63: P1 | K63: P2 | L63: P3 | M63: P4 | N63: P5 | O63: P6 | Q63: Tarifa | R63: P1 | S63: P2 | T63: P3 | U63: P4 | V63: P5 | W63: P6
A64: 2.0TD | B64: 27.704413 | C64: 0.725423 | I64: 2.0TD | J64: =B64/365 -> 0.075902501 | K64: =C64/365 -> 0.0019874603 | Q64: 2.0TD | R64: =B64/12 -> 2.3087011 | S64: =C64/12 -> 0.060451917
A65: 3.0TD | B65: 20.376927 | C65: 10.617621 | D65: 4.481534 | E65: 3.886333 | F65: 2.513851 | G65: 1.442287 | I65: 3.0TD | J65: =B65/365 -> 0.055827197 | K65: =C65/365 -> 0.029089373 | L65: =D65/365 -> 0.012278175 | M65: =E65/365 -> 0.010647488 | N65: =F65/365 -> 0.006887263 | O65: =G65/365 -> 0.0039514712 | Q65: 3.0TD | R65: =B65/12 -> 1.6980772 | S65: =C65/12 -> 0.88480175 | T65: =D65/12 -> 0.37346117 | U65: =E65/12 -> 0.32386108 | V65: =F65/12 -> 0.20948758 | W65: =G65/12 -> 0.12019058
...
